}  const signOut = async () => {    const { error } = await supabase.auth.signOut()    return { error }    try {      console.log('Signing out user...')      const { error } = await supabase.auth.signOut()      if (error) {        console.error('Signout error:', error)        return { error }      }            console.log('Signout successful')      // Clear local state      setUser(null)      setSession(null)      setLoading(false)            return { error: null }    } catch (err) {      console.error('Signout exception:', err)      return { error: err }    }  }  return {
‎client/src/pages/DashboardPage.tsxCopy file name to clipboardExpand all lines: client/src/pages/DashboardPage.tsx+39-6Lines changed: 39 additions & 6 deletionsOriginal file line numberDiff line numberDiff line change@@ -17,34 +17,61 @@ export function DashboardPage() {  useEffect(() => {    if (user) {      fetchUserPlans()    } else if (!user && !loading) {      // If no user and not loading, redirect to home      window.location.hash = '#/'    }  }, [user])  }, [user, loading])  const fetchUserPlans = async () => {    try {      console.log('Fetching user plans for user ID:', user?.id)            // Fetch user's hobby plans      const { data: plansData, error: plansError } = await supabase        .from('hobby_plans')        .select('*')        .eq('user_id', user?.id)        .order('created_at', { ascending: false })      if (plansError) throw plansError      if (plansError) {        console.error('Plans error:', plansError)        // If table doesn't exist, just set empty data        if (plansError.message?.includes('relation') || plansError.message?.includes('does not exist')) {          setPlans([])          setProgress([])          setLoading(false)          return        }        throw plansError      }      // Fetch user's progress      const { data: progressData, error: progressError } = await supabase        .from('user_progress')        .select('*')        .eq('user_id', user?.id)      if (progressError) throw progressError      if (progressError) {        console.error('Progress error:', progressError)        // If table doesn't exist, just set empty data        if (progressError.message?.includes('relation') || progressError.message?.includes('does not exist')) {          setProgress([])        } else {          throw progressError        }      }      console.log('Fetched plans:', plansData?.length || 0)      console.log('Fetched progress:', progressData?.length || 0)            setPlans(plansData || [])      setProgress(progressData || [])    } catch (error: any) {      console.error('Dashboard fetch error:', error)      toast({        title: "Error",        description: "Failed to load your dashboard data.",        description: error.message || "Failed to load your dashboard data.",        variant: "destructive",      })    } finally {@@ -54,15 +81,21 @@ export function DashboardPage() {  const handleSignOut = async () => {    try {      await signOut()      const { error } = await signOut()      if (error) throw error            toast({        title: "Signed out",        description: "You've been successfully signed out.",      })            // Redirect to home page after successful signout      window.location.hash = '#/'    } catch (error: any) {      console.error('Signout error:', error)      toast({        title: "Error",        description: "Failed to sign out.",        description: error.message || "Failed to sign out.",        variant: "destructive",      })    }


ChatGPT said:
You're showing a snippet of a refactor or patch to a DashboardPage.tsx in a React app using Supabase for authentication and storage.

There’s one specific concern here:

❗ Problem in signOut Function:
ts
Copy
Edit
const signOut = async () => {
  const { error } = await supabase.auth.signOut()
  return { error } // <-- this return happens **before** the try-catch block

  try {
    ...
  } catch (err) {
    ...
  }
}
This line:

ts
Copy
Edit
return { error }
exits the function immediately, so the try block is never executed. The whole block below it is dead code and will never run.

✅ Fix: Move the signOut logic entirely into the try block:
ts
Copy
Edit
const signOut = async () => {
  try {
    console.log('Signing out user...')
    const { error } = await supabase.auth.signOut()

    if (error) {
      console.error('Signout error:', error)
      return { error }
    }

    console.log('Signout successful')

    // Clear local state
    setUser(null)
    setSession(null)
    setLoading(false)

    return { error: null }
  } catch (err) {
    console.error('Signout exception:', err)
    return { error: err }
  }
}
✅ Then in handleSignOut, you're calling:
ts
Copy
Edit
const { error } = await signOut()
if (error) throw error
That looks fine — it shows a toast and redirects based on success or failure.

✅ Summary of Fixes Needed
Remove the early return { error } in signOut().

Wrap everything in a try/catch, as intended.